python: can't open file 'cralwer.py': [Errno 2] No such file or directory
Crawling...1/1686
Crawling...2/1686
Crawling...3/1686
Crawling...4/1686
Crawling...5/1686
Crawling...6/1686
Crawling...7/1686
Crawling...8/1686
Crawling...9/1686
Crawling...10/1686
Crawling...11/1686
Crawling...12/1686
Crawling...13/1686
Crawling...14/1686
Crawling...15/1686
Crawling...16/1686
Crawling...17/1686
Crawling...18/1686
Crawling...19/1686
Crawling...20/1686
Crawling...21/1686
Crawling...22/1686
Crawling...23/1686
Crawling...24/1686
Crawling...25/1686
Crawling...26/1686
Crawling...27/1686
Crawling...28/1686
Crawling...29/1686
Crawling...30/1686
Crawling...31/1686
Crawling...32/1686
Crawling...33/1686
Crawling...34/1686
Crawling...35/1686
Crawling...36/1686
Crawling...37/1686
Crawling...38/1686
Crawling...39/1686
Crawling...40/1686
Crawling...41/1686
Crawling...42/1686
Crawling...43/1686
Crawling...44/1686
Crawling...45/1686
Crawling...46/1686
Crawling...47/1686
Crawling...48/1686
Crawling...49/1686
Crawling...50/1686
Crawling...51/1686
Crawling...52/1686
Crawling...53/1686
Crawling...54/1686
Crawling...55/1686
Crawling...56/1686
Crawling...57/1686
Crawling...58/1686
Crawling...59/1686
Crawling...60/1686
Crawling...61/1686
Crawling...62/1686
Crawling...63/1686
Crawling...64/1686
Crawling...65/1686
Crawling...66/1686
Crawling...67/1686
Crawling...68/1686
Crawling...69/1686
Crawling...70/1686
Crawling...71/1686
Crawling...72/1686
Crawling...73/1686
Crawling...74/1686
Crawling...75/1686
Crawling...76/1686
Crawling...77/1686
Crawling...78/1686
Crawling...79/1686
Crawling...80/1686
Crawling...81/1686
Crawling...82/1686
Crawling...83/1686
Crawling...84/1686
Crawling...85/1686
Crawling...86/1686
Crawling...87/1686
Crawling...88/1686
Crawling...89/1686
Crawling...90/1686
Crawling...91/1686
Crawling...92/1686
Crawling...93/1686
Crawling...94/1686
Crawling...95/1686
Crawling...96/1686
Crawling...97/1686
Crawling...98/1686
Crawling...99/1686
Crawling...100/1686
Crawling...101/1686
Crawling...102/1686
Crawling...103/1686
Crawling...104/1686
Crawling...105/1686
Crawling...106/1686
Crawling...107/1686
Crawling...108/1686
Crawling...109/1686
Crawling...110/1686
Crawling...111/1686
Crawling...112/1686
Crawling...113/1686
Crawling...114/1686
Crawling...115/1686
Crawling...116/1686
Crawling...117/1686
Crawling...118/1686
Crawling...119/1686
Crawling...120/1686
Crawling...121/1686
Crawling...122/1686
Crawling...123/1686
Crawling...124/1686
Crawling...125/1686
Crawling...126/1686
Crawling...127/1686
Crawling...128/1686
Crawling...129/1686
Crawling...130/1686
Crawling...131/1686
Crawling...132/1686
Crawling...133/1686
Crawling...134/1686
Traceback (most recent call last):
  File "/opt/anaconda3/lib/python3.8/site-packages/urllib3/connection.py", line 159, in _new_conn
    conn = connection.create_connection(
  File "/opt/anaconda3/lib/python3.8/site-packages/urllib3/util/connection.py", line 84, in create_connection
    raise err
  File "/opt/anaconda3/lib/python3.8/site-packages/urllib3/util/connection.py", line 74, in create_connection
    sock.connect(sa)
ConnectionRefusedError: [Errno 111] Connection refused

During handling of the above exception, another exception occurred:

Traceback (most recent call last):
  File "/opt/anaconda3/lib/python3.8/site-packages/urllib3/connectionpool.py", line 670, in urlopen
    httplib_response = self._make_request(
  File "/opt/anaconda3/lib/python3.8/site-packages/urllib3/connectionpool.py", line 381, in _make_request
    self._validate_conn(conn)
  File "/opt/anaconda3/lib/python3.8/site-packages/urllib3/connectionpool.py", line 976, in _validate_conn
    conn.connect()
  File "/opt/anaconda3/lib/python3.8/site-packages/urllib3/connection.py", line 308, in connect
    conn = self._new_conn()
  File "/opt/anaconda3/lib/python3.8/site-packages/urllib3/connection.py", line 171, in _new_conn
    raise NewConnectionError(
urllib3.exceptions.NewConnectionError: <urllib3.connection.HTTPSConnection object at 0x7f35005f7fd0>: Failed to establish a new connection: [Errno 111] Connection refused

During handling of the above exception, another exception occurred:

Traceback (most recent call last):
  File "/opt/anaconda3/lib/python3.8/site-packages/requests/adapters.py", line 439, in send
    resp = conn.urlopen(
  File "/opt/anaconda3/lib/python3.8/site-packages/urllib3/connectionpool.py", line 724, in urlopen
    retries = retries.increment(
  File "/opt/anaconda3/lib/python3.8/site-packages/urllib3/util/retry.py", line 439, in increment
    raise MaxRetryError(_pool, url, error or ResponseError(cause))
urllib3.exceptions.MaxRetryError: HTTPSConnectionPool(host='nflcombineresults.com', port=443): Max retries exceeded with url: /playerpage.php?f=Moe&l=Ways&i=27909 (Caused by NewConnectionError('<urllib3.connection.HTTPSConnection object at 0x7f35005f7fd0>: Failed to establish a new connection: [Errno 111] Connection refused'))

During handling of the above exception, another exception occurred:

Traceback (most recent call last):
  File "crawler.py", line 228, in <module>
    main()
  File "crawler.py", line 217, in main
    crawl_show_pages(test_urls, player_names, draft_years)
  File "crawler.py", line 140, in crawl_show_pages
    combine_show_response = requests.get(url)
  File "/opt/anaconda3/lib/python3.8/site-packages/requests/api.py", line 76, in get
    return request('get', url, params=params, **kwargs)
  File "/opt/anaconda3/lib/python3.8/site-packages/requests/api.py", line 61, in request
    return session.request(method=method, url=url, **kwargs)
  File "/opt/anaconda3/lib/python3.8/site-packages/requests/sessions.py", line 530, in request
    resp = self.send(prep, **send_kwargs)
  File "/opt/anaconda3/lib/python3.8/site-packages/requests/sessions.py", line 643, in send
    r = adapter.send(request, **kwargs)
  File "/opt/anaconda3/lib/python3.8/site-packages/requests/adapters.py", line 516, in send
    raise ConnectionError(e, request=request)
requests.exceptions.ConnectionError: HTTPSConnectionPool(host='nflcombineresults.com', port=443): Max retries exceeded with url: /playerpage.php?f=Moe&l=Ways&i=27909 (Caused by NewConnectionError('<urllib3.connection.HTTPSConnection object at 0x7f35005f7fd0>: Failed to establish a new connection: [Errno 111] Connection refused'))
